python manage.py runserver
Performing system checks...

System check identified no issues (0 silenced).
Unhandled exception in thread started by <function check_errors.<locals>.wrapper at 0x7f5a9c2c9510>
Traceback (most recent call last):
  File "/home/pavel/.virtualenvs/sandbox/lib/python3.5/site-packages/django/db/backends/base/base.py", line 213, in ensure_connection
    self.connect()
  File "/home/pavel/.virtualenvs/sandbox/lib/python3.5/site-packages/django/db/backends/base/base.py", line 189, in connect
    self.connection = self.get_new_connection(conn_params)
  File "/home/pavel/.virtualenvs/sandbox/lib/python3.5/site-packages/django/db/backends/postgresql/base.py", line 176, in get_new_connection
    connection = Database.connect(**conn_params)
  File "/home/pavel/.virtualenvs/sandbox/lib/python3.5/site-packages/psycopg2/__init__.py", line 130, in connect
    conn = _connect(dsn, connection_factory=connection_factory, **kwasync)
psycopg2.OperationalError: could not connect to server: Connection timed out
	Is the server running on host "192.168.1.21" and accepting
	TCP/IP connections on port 5432?


The above exception was the direct cause of the following exception:

Traceback (most recent call last):
  File "/home/pavel/.virtualenvs/sandbox/lib/python3.5/site-packages/django/utils/autoreload.py", line 227, in wrapper
    fn(*args, **kwargs)
  File "/home/pavel/.virtualenvs/sandbox/lib/python3.5/site-packages/django/core/management/commands/runserver.py", line 128, in inner_run
    self.check_migrations()
  File "/home/pavel/.virtualenvs/sandbox/lib/python3.5/site-packages/django/core/management/base.py", line 422, in check_migrations
    executor = MigrationExecutor(connections[DEFAULT_DB_ALIAS])
  File "/home/pavel/.virtualenvs/sandbox/lib/python3.5/site-packages/django/db/migrations/executor.py", line 20, in __init__
    self.loader = MigrationLoader(self.connection)
  File "/home/pavel/.virtualenvs/sandbox/lib/python3.5/site-packages/django/db/migrations/loader.py", line 52, in __init__
    self.build_graph()
  File "/home/pavel/.virtualenvs/sandbox/lib/python3.5/site-packages/django/db/migrations/loader.py", line 209, in build_graph
    self.applied_migrations = recorder.applied_migrations()
  File "/home/pavel/.virtualenvs/sandbox/lib/python3.5/site-packages/django/db/migrations/recorder.py", line 65, in applied_migrations
    self.ensure_schema()
  File "/home/pavel/.virtualenvs/sandbox/lib/python3.5/site-packages/django/db/migrations/recorder.py", line 52, in ensure_schema
    if self.Migration._meta.db_table in self.connection.introspection.table_names(self.connection.cursor()):
  File "/home/pavel/.virtualenvs/sandbox/lib/python3.5/site-packages/django/db/backends/base/base.py", line 254, in cursor
    return self._cursor()
  File "/home/pavel/.virtualenvs/sandbox/lib/python3.5/site-packages/django/db/backends/base/base.py", line 229, in _cursor
    self.ensure_connection()
  File "/home/pavel/.virtualenvs/sandbox/lib/python3.5/site-packages/django/db/backends/base/base.py", line 213, in ensure_connection
    self.connect()
  File "/home/pavel/.virtualenvs/sandbox/lib/python3.5/site-packages/django/db/utils.py", line 94, in __exit__
    six.reraise(dj_exc_type, dj_exc_value, traceback)
  File "/home/pavel/.virtualenvs/sandbox/lib/python3.5/site-packages/django/utils/six.py", line 685, in reraise
    raise value.with_traceback(tb)
  File "/home/pavel/.virtualenvs/sandbox/lib/python3.5/site-packages/django/db/backends/base/base.py", line 213, in ensure_connection
    self.connect()
  File "/home/pavel/.virtualenvs/sandbox/lib/python3.5/site-packages/django/db/backends/base/base.py", line 189, in connect
    self.connection = self.get_new_connection(conn_params)
  File "/home/pavel/.virtualenvs/sandbox/lib/python3.5/site-packages/django/db/backends/postgresql/base.py", line 176, in get_new_connection
    connection = Database.connect(**conn_params)
  File "/home/pavel/.virtualenvs/sandbox/lib/python3.5/site-packages/psycopg2/__init__.py", line 130, in connect
    conn = _connect(dsn, connection_factory=connection_factory, **kwasync)
django.db.utils.OperationalError: could not connect to server: Connection timed out
	Is the server running on host "192.168.1.21" and accepting
	TCP/IP connections on port 5432?
